[2025-03-07T09:19:42.611+0000] {local_task_job_runner.py:120} INFO - ::group::Pre task execution logs
[2025-03-07T09:19:42.638+0000] {taskinstance.py:2073} INFO - Dependencies all met for dep_context=non-requeueable deps ti=<TaskInstance: clientes_dag.gx_run_audit manual__2025-03-07T09:19:39.641330+00:00 [queued]>
[2025-03-07T09:19:42.646+0000] {taskinstance.py:2073} INFO - Dependencies all met for dep_context=requeueable deps ti=<TaskInstance: clientes_dag.gx_run_audit manual__2025-03-07T09:19:39.641330+00:00 [queued]>
[2025-03-07T09:19:42.646+0000] {taskinstance.py:2303} INFO - Starting attempt 1 of 1
[2025-03-07T09:19:42.659+0000] {taskinstance.py:2327} INFO - Executing <Task(PythonOperator): gx_run_audit> on 2025-03-07 09:19:39.641330+00:00
[2025-03-07T09:19:42.666+0000] {standard_task_runner.py:63} INFO - Started process 860 to run task
[2025-03-07T09:19:42.671+0000] {standard_task_runner.py:90} INFO - Running: ['***', 'tasks', 'run', 'clientes_dag', 'gx_run_audit', 'manual__2025-03-07T09:19:39.641330+00:00', '--job-id', '3', '--raw', '--subdir', 'DAGS_FOLDER/clientes_dag.py', '--cfg-path', '/tmp/tmpjto949e6']
[2025-03-07T09:19:42.674+0000] {standard_task_runner.py:91} INFO - Job 3: Subtask gx_run_audit
[2025-03-07T09:19:42.717+0000] {task_command.py:426} INFO - Running <TaskInstance: clientes_dag.gx_run_audit manual__2025-03-07T09:19:39.641330+00:00 [running]> on host 658b8f6e1c0c
[2025-03-07T09:19:43.063+0000] {taskinstance.py:2644} INFO - Exporting env vars: AIRFLOW_CTX_DAG_OWNER='***' AIRFLOW_CTX_DAG_ID='clientes_dag' AIRFLOW_CTX_TASK_ID='gx_run_audit' AIRFLOW_CTX_EXECUTION_DATE='2025-03-07T09:19:39.641330+00:00' AIRFLOW_CTX_TRY_NUMBER='1' AIRFLOW_CTX_DAG_RUN_ID='manual__2025-03-07T09:19:39.641330+00:00'
[2025-03-07T09:19:43.065+0000] {taskinstance.py:430} INFO - ::endgroup::
[2025-03-07T09:19:43.110+0000] {file_data_context.py:209} INFO - FileDataContext loading fluent config
[2025-03-07T09:19:43.113+0000] {config.py:191} INFO - Loading 'datasources' ->
[{'assets': [...],
  'connection_string': 'postgresql+psycopg2://postgres:postgres@localhost:5432/postgres',
  'id': '0fde3ca8-3d39-44d3-9eaa-63d03fd0de9f',
  'name': 'pg_datasource',
  'type': 'postgres'}]
[2025-03-07T09:19:43.174+0000] {abstract_data_context.py:2416} INFO - Loaded 'pg_datasource' from fluent config
[2025-03-07T09:19:43.184+0000] {batch_filter.py:243} INFO - batch_slice: None was parsed to: slice(0, None, None)
[2025-03-07T09:19:43.187+0000] {expectation.py:1137} INFO - _get_default_value called with key "table", but it is not a known field
[2025-03-07T09:19:43.187+0000] {expectation.py:1137} INFO - _get_default_value called with key "table", but it is not a known field
[2025-03-07T09:19:43.188+0000] {expectation.py:1137} INFO - _get_default_value called with key "table", but it is not a known field
[2025-03-07T09:19:43.189+0000] {expectation.py:1137} INFO - _get_default_value called with key "table", but it is not a known field
[2025-03-07T09:19:43.190+0000] {expectation.py:1137} INFO - _get_default_value called with key "table", but it is not a known field
[2025-03-07T09:19:43.190+0000] {expectation.py:1137} INFO - _get_default_value called with key "table", but it is not a known field
[2025-03-07T09:19:43.191+0000] {expectation.py:1137} INFO - _get_default_value called with key "table", but it is not a known field
[2025-03-07T09:19:43.202+0000] {expectation.py:1137} INFO - _get_default_value called with key "table", but it is not a known field
[2025-03-07T09:19:43.203+0000] {expectation.py:1137} INFO - _get_default_value called with key "table", but it is not a known field
[2025-03-07T09:19:43.203+0000] {expectation.py:1137} INFO - _get_default_value called with key "table", but it is not a known field
[2025-03-07T09:19:43.204+0000] {expectation.py:1137} INFO - _get_default_value called with key "table", but it is not a known field
[2025-03-07T09:19:43.205+0000] {expectation.py:1137} INFO - _get_default_value called with key "table", but it is not a known field
[2025-03-07T09:19:43.205+0000] {expectation.py:1137} INFO - _get_default_value called with key "table", but it is not a known field
[2025-03-07T09:19:43.206+0000] {expectation.py:1137} INFO - _get_default_value called with key "table", but it is not a known field
[2025-03-07T09:19:43.216+0000] {expectation.py:1137} INFO - _get_default_value called with key "table", but it is not a known field
[2025-03-07T09:19:43.217+0000] {expectation.py:1137} INFO - _get_default_value called with key "table", but it is not a known field
[2025-03-07T09:19:43.218+0000] {expectation.py:1137} INFO - _get_default_value called with key "table", but it is not a known field
[2025-03-07T09:19:43.219+0000] {expectation.py:1137} INFO - _get_default_value called with key "table", but it is not a known field
[2025-03-07T09:19:43.220+0000] {expectation.py:1137} INFO - _get_default_value called with key "table", but it is not a known field
[2025-03-07T09:19:43.220+0000] {expectation.py:1137} INFO - _get_default_value called with key "table", but it is not a known field
[2025-03-07T09:19:43.221+0000] {expectation.py:1137} INFO - _get_default_value called with key "table", but it is not a known field
[2025-03-07T09:19:43.231+0000] {expectation.py:1137} INFO - _get_default_value called with key "table", but it is not a known field
[2025-03-07T09:19:43.232+0000] {expectation.py:1137} INFO - _get_default_value called with key "table", but it is not a known field
[2025-03-07T09:19:43.233+0000] {expectation.py:1137} INFO - _get_default_value called with key "table", but it is not a known field
[2025-03-07T09:19:43.234+0000] {expectation.py:1137} INFO - _get_default_value called with key "table", but it is not a known field
[2025-03-07T09:19:43.235+0000] {expectation.py:1137} INFO - _get_default_value called with key "table", but it is not a known field
[2025-03-07T09:19:43.235+0000] {expectation.py:1137} INFO - _get_default_value called with key "table", but it is not a known field
[2025-03-07T09:19:43.236+0000] {expectation.py:1137} INFO - _get_default_value called with key "table", but it is not a known field
[2025-03-07T09:19:43.247+0000] {expectation.py:1137} INFO - _get_default_value called with key "table", but it is not a known field
[2025-03-07T09:19:43.248+0000] {expectation.py:1137} INFO - _get_default_value called with key "table", but it is not a known field
[2025-03-07T09:19:43.249+0000] {expectation.py:1137} INFO - _get_default_value called with key "table", but it is not a known field
[2025-03-07T09:19:43.250+0000] {expectation.py:1137} INFO - _get_default_value called with key "table", but it is not a known field
[2025-03-07T09:19:43.251+0000] {expectation.py:1137} INFO - _get_default_value called with key "table", but it is not a known field
[2025-03-07T09:19:43.252+0000] {expectation.py:1137} INFO - _get_default_value called with key "table", but it is not a known field
[2025-03-07T09:19:43.252+0000] {expectation.py:1137} INFO - _get_default_value called with key "table", but it is not a known field
[2025-03-07T09:19:43.266+0000] {expectation.py:1137} INFO - _get_default_value called with key "table", but it is not a known field
[2025-03-07T09:19:43.267+0000] {expectation.py:1137} INFO - _get_default_value called with key "table", but it is not a known field
[2025-03-07T09:19:43.268+0000] {expectation.py:1137} INFO - _get_default_value called with key "table", but it is not a known field
[2025-03-07T09:19:43.269+0000] {expectation.py:1137} INFO - _get_default_value called with key "table", but it is not a known field
[2025-03-07T09:19:43.270+0000] {expectation.py:1137} INFO - _get_default_value called with key "table", but it is not a known field
[2025-03-07T09:19:43.271+0000] {expectation.py:1137} INFO - _get_default_value called with key "table", but it is not a known field
[2025-03-07T09:19:43.271+0000] {expectation.py:1137} INFO - _get_default_value called with key "table", but it is not a known field
[2025-03-07T09:19:43.287+0000] {expectation.py:1137} INFO - _get_default_value called with key "table", but it is not a known field
[2025-03-07T09:19:43.288+0000] {expectation.py:1137} INFO - _get_default_value called with key "table", but it is not a known field
[2025-03-07T09:19:43.289+0000] {expectation.py:1137} INFO - _get_default_value called with key "table", but it is not a known field
[2025-03-07T09:19:43.289+0000] {expectation.py:1137} INFO - _get_default_value called with key "table", but it is not a known field
[2025-03-07T09:19:43.290+0000] {expectation.py:1137} INFO - _get_default_value called with key "table", but it is not a known field
[2025-03-07T09:19:43.291+0000] {expectation.py:1137} INFO - _get_default_value called with key "table", but it is not a known field
[2025-03-07T09:19:43.291+0000] {expectation.py:1137} INFO - _get_default_value called with key "table", but it is not a known field
[2025-03-07T09:19:43.304+0000] {expectation.py:1137} INFO - _get_default_value called with key "table", but it is not a known field
[2025-03-07T09:19:43.305+0000] {expectation.py:1137} INFO - _get_default_value called with key "table", but it is not a known field
[2025-03-07T09:19:43.306+0000] {expectation.py:1137} INFO - _get_default_value called with key "table", but it is not a known field
[2025-03-07T09:19:43.307+0000] {expectation.py:1137} INFO - _get_default_value called with key "table", but it is not a known field
[2025-03-07T09:19:43.308+0000] {expectation.py:1137} INFO - _get_default_value called with key "table", but it is not a known field
[2025-03-07T09:19:43.309+0000] {expectation.py:1137} INFO - _get_default_value called with key "table", but it is not a known field
[2025-03-07T09:19:43.310+0000] {expectation.py:1137} INFO - _get_default_value called with key "table", but it is not a known field
[2025-03-07T09:19:43.360+0000] {logging_mixin.py:188} WARNING - Calculating Metrics:   0%|          | 0/61 [00:00<?, ?it/s]
[2025-03-07T09:19:43.360+0000] {logging_mixin.py:188} WARNING - Calculating Metrics:   0%|          | 0/61 [00:00<?, ?it/s]
[2025-03-07T09:19:43.392+0000] {logging_mixin.py:188} WARNING - Calculating Metrics:   0%|          | 0/61 [00:00<?, ?it/s]
[2025-03-07T09:19:43.419+0000] {logging_mixin.py:188} WARNING - Calculating Metrics:   0%|          | 0/61 [00:00<?, ?it/s]
[2025-03-07T09:19:43.447+0000] {logging_mixin.py:188} WARNING - Calculating Metrics:   0%|          | 0/61 [00:00<?, ?it/s]
[2025-03-07T09:19:43.475+0000] {logging_mixin.py:188} WARNING - Calculating Metrics:   0%|          | 0/61 [00:00<?, ?it/s]
[2025-03-07T09:19:43.476+0000] {logging_mixin.py:188} WARNING - Calculating Metrics:   0%|          | 0/61 [00:00<?, ?it/s]
[2025-03-07T09:19:43.503+0000] {logging_mixin.py:188} WARNING - Calculating Metrics:   0%|          | 0/61 [00:00<?, ?it/s]
[2025-03-07T09:19:43.533+0000] {logging_mixin.py:188} WARNING - Calculating Metrics:   0%|          | 0/61 [00:00<?, ?it/s]
[2025-03-07T09:19:43.535+0000] {logging_mixin.py:188} WARNING - Calculating Metrics:   3%|3         | 2/61 [00:00<00:05, 11.44it/s]
[2025-03-07T09:19:43.564+0000] {logging_mixin.py:188} WARNING - Calculating Metrics:   3%|3         | 2/61 [00:00<00:06,  9.81it/s]
[2025-03-07T09:19:43.569+0000] {sqlalchemy_execution_engine.py:1041} ERROR - An SQL execution Exception occurred.  OperationalError: "(psycopg2.OperationalError) connection to server at "localhost" (::1), port 5432 failed: Connection refused
	Is the server running on that host and accepting TCP/IP connections?
connection to server at "localhost" (127.0.0.1), port 5432 failed: Connection refused
	Is the server running on that host and accepting TCP/IP connections?

(Background on this error at: https://sqlalche.me/e/14/e3q8)".  Traceback: "Traceback (most recent call last):
  File "/home/***/.local/lib/python3.11/site-packages/sqlalchemy/engine/base.py", line 3371, in _wrap_pool_connect
    return fn()
           ^^^^
  File "/home/***/.local/lib/python3.11/site-packages/sqlalchemy/pool/base.py", line 327, in connect
    return _ConnectionFairy._checkout(self)
           ^^^^^^^^^^^^^^^^^^^^^^^^^^^^^^^^
  File "/home/***/.local/lib/python3.11/site-packages/sqlalchemy/pool/base.py", line 894, in _checkout
    fairy = _ConnectionRecord.checkout(pool)
            ^^^^^^^^^^^^^^^^^^^^^^^^^^^^^^^^
  File "/home/***/.local/lib/python3.11/site-packages/sqlalchemy/pool/base.py", line 493, in checkout
    rec = pool._do_get()
          ^^^^^^^^^^^^^^
  File "/home/***/.local/lib/python3.11/site-packages/sqlalchemy/pool/impl.py", line 145, in _do_get
    with util.safe_reraise():
  File "/home/***/.local/lib/python3.11/site-packages/sqlalchemy/util/langhelpers.py", line 70, in __exit__
    compat.raise_(
  File "/home/***/.local/lib/python3.11/site-packages/sqlalchemy/util/compat.py", line 211, in raise_
    raise exception
  File "/home/***/.local/lib/python3.11/site-packages/sqlalchemy/pool/impl.py", line 143, in _do_get
    return self._create_connection()
           ^^^^^^^^^^^^^^^^^^^^^^^^^
  File "/home/***/.local/lib/python3.11/site-packages/sqlalchemy/pool/base.py", line 273, in _create_connection
    return _ConnectionRecord(self)
           ^^^^^^^^^^^^^^^^^^^^^^^
  File "/home/***/.local/lib/python3.11/site-packages/sqlalchemy/pool/base.py", line 388, in __init__
    self.__connect()
  File "/home/***/.local/lib/python3.11/site-packages/sqlalchemy/pool/base.py", line 690, in __connect
    with util.safe_reraise():
  File "/home/***/.local/lib/python3.11/site-packages/sqlalchemy/util/langhelpers.py", line 70, in __exit__
    compat.raise_(
  File "/home/***/.local/lib/python3.11/site-packages/sqlalchemy/util/compat.py", line 211, in raise_
    raise exception
  File "/home/***/.local/lib/python3.11/site-packages/sqlalchemy/pool/base.py", line 686, in __connect
    self.dbapi_connection = connection = pool._invoke_creator(self)
                                         ^^^^^^^^^^^^^^^^^^^^^^^^^^
  File "/home/***/.local/lib/python3.11/site-packages/sqlalchemy/engine/create.py", line 574, in connect
    return dialect.connect(*cargs, **cparams)
           ^^^^^^^^^^^^^^^^^^^^^^^^^^^^^^^^^^
  File "/home/***/.local/lib/python3.11/site-packages/sqlalchemy/engine/default.py", line 598, in connect
    return self.dbapi.connect(*cargs, **cparams)
           ^^^^^^^^^^^^^^^^^^^^^^^^^^^^^^^^^^^^^
  File "/home/***/.local/lib/python3.11/site-packages/psycopg2/__init__.py", line 122, in connect
    conn = _connect(dsn, connection_factory=connection_factory, **kwasync)
           ^^^^^^^^^^^^^^^^^^^^^^^^^^^^^^^^^^^^^^^^^^^^^^^^^^^^^^^^^^^^^^^
psycopg2.OperationalError: connection to server at "localhost" (::1), port 5432 failed: Connection refused
	Is the server running on that host and accepting TCP/IP connections?
connection to server at "localhost" (127.0.0.1), port 5432 failed: Connection refused
	Is the server running on that host and accepting TCP/IP connections?


The above exception was the direct cause of the following exception:

Traceback (most recent call last):
  File "/home/***/.local/lib/python3.11/site-packages/great_expectations/execution_engine/sqlalchemy_execution_engine.py", line 1029, in resolve_metric_bundle
    res = self.execute_query(sa_query_object).fetchall()
          ^^^^^^^^^^^^^^^^^^^^^^^^^^^^^^^^^^^
  File "/home/***/.local/lib/python3.11/site-packages/great_expectations/execution_engine/sqlalchemy_execution_engine.py", line 1319, in execute_query
    with self.get_connection() as connection:
  File "/usr/local/lib/python3.11/contextlib.py", line 137, in __enter__
    return next(self.gen)
           ^^^^^^^^^^^^^^
  File "/home/***/.local/lib/python3.11/site-packages/great_expectations/execution_engine/sqlalchemy_execution_engine.py", line 1304, in get_connection
    with self.engine.connect() as connection:
         ^^^^^^^^^^^^^^^^^^^^^
  File "/home/***/.local/lib/python3.11/site-packages/sqlalchemy/engine/base.py", line 3325, in connect
    return self._connection_cls(self, close_with_result=close_with_result)
           ^^^^^^^^^^^^^^^^^^^^^^^^^^^^^^^^^^^^^^^^^^^^^^^^^^^^^^^^^^^^^^^
  File "/home/***/.local/lib/python3.11/site-packages/sqlalchemy/engine/base.py", line 96, in __init__
    else engine.raw_connection()
         ^^^^^^^^^^^^^^^^^^^^^^^
  File "/home/***/.local/lib/python3.11/site-packages/sqlalchemy/engine/base.py", line 3404, in raw_connection
    return self._wrap_pool_connect(self.pool.connect, _connection)
           ^^^^^^^^^^^^^^^^^^^^^^^^^^^^^^^^^^^^^^^^^^^^^^^^^^^^^^^
  File "/home/***/.local/lib/python3.11/site-packages/sqlalchemy/engine/base.py", line 3374, in _wrap_pool_connect
    Connection._handle_dbapi_exception_noconnection(
  File "/home/***/.local/lib/python3.11/site-packages/sqlalchemy/engine/base.py", line 2208, in _handle_dbapi_exception_noconnection
    util.raise_(
  File "/home/***/.local/lib/python3.11/site-packages/sqlalchemy/util/compat.py", line 211, in raise_
    raise exception
  File "/home/***/.local/lib/python3.11/site-packages/sqlalchemy/engine/base.py", line 3371, in _wrap_pool_connect
    return fn()
           ^^^^
  File "/home/***/.local/lib/python3.11/site-packages/sqlalchemy/pool/base.py", line 327, in connect
    return _ConnectionFairy._checkout(self)
           ^^^^^^^^^^^^^^^^^^^^^^^^^^^^^^^^
  File "/home/***/.local/lib/python3.11/site-packages/sqlalchemy/pool/base.py", line 894, in _checkout
    fairy = _ConnectionRecord.checkout(pool)
            ^^^^^^^^^^^^^^^^^^^^^^^^^^^^^^^^
  File "/home/***/.local/lib/python3.11/site-packages/sqlalchemy/pool/base.py", line 493, in checkout
    rec = pool._do_get()
          ^^^^^^^^^^^^^^
  File "/home/***/.local/lib/python3.11/site-packages/sqlalchemy/pool/impl.py", line 145, in _do_get
    with util.safe_reraise():
  File "/home/***/.local/lib/python3.11/site-packages/sqlalchemy/util/langhelpers.py", line 70, in __exit__
    compat.raise_(
  File "/home/***/.local/lib/python3.11/site-packages/sqlalchemy/util/compat.py", line 211, in raise_
    raise exception
  File "/home/***/.local/lib/python3.11/site-packages/sqlalchemy/pool/impl.py", line 143, in _do_get
    return self._create_connection()
           ^^^^^^^^^^^^^^^^^^^^^^^^^
  File "/home/***/.local/lib/python3.11/site-packages/sqlalchemy/pool/base.py", line 273, in _create_connection
    return _ConnectionRecord(self)
           ^^^^^^^^^^^^^^^^^^^^^^^
  File "/home/***/.local/lib/python3.11/site-packages/sqlalchemy/pool/base.py", line 388, in __init__
    self.__connect()
  File "/home/***/.local/lib/python3.11/site-packages/sqlalchemy/pool/base.py", line 690, in __connect
    with util.safe_reraise():
  File "/home/***/.local/lib/python3.11/site-packages/sqlalchemy/util/langhelpers.py", line 70, in __exit__
    compat.raise_(
  File "/home/***/.local/lib/python3.11/site-packages/sqlalchemy/util/compat.py", line 211, in raise_
    raise exception
  File "/home/***/.local/lib/python3.11/site-packages/sqlalchemy/pool/base.py", line 686, in __connect
    self.dbapi_connection = connection = pool._invoke_creator(self)
                                         ^^^^^^^^^^^^^^^^^^^^^^^^^^
  File "/home/***/.local/lib/python3.11/site-packages/sqlalchemy/engine/create.py", line 574, in connect
    return dialect.connect(*cargs, **cparams)
           ^^^^^^^^^^^^^^^^^^^^^^^^^^^^^^^^^^
  File "/home/***/.local/lib/python3.11/site-packages/sqlalchemy/engine/default.py", line 598, in connect
    return self.dbapi.connect(*cargs, **cparams)
           ^^^^^^^^^^^^^^^^^^^^^^^^^^^^^^^^^^^^^
  File "/home/***/.local/lib/python3.11/site-packages/psycopg2/__init__.py", line 122, in connect
    conn = _connect(dsn, connection_factory=connection_factory, **kwasync)
           ^^^^^^^^^^^^^^^^^^^^^^^^^^^^^^^^^^^^^^^^^^^^^^^^^^^^^^^^^^^^^^^
sqlalchemy.exc.OperationalError: (psycopg2.OperationalError) connection to server at "localhost" (::1), port 5432 failed: Connection refused
	Is the server running on that host and accepting TCP/IP connections?
connection to server at "localhost" (127.0.0.1), port 5432 failed: Connection refused
	Is the server running on that host and accepting TCP/IP connections?

(Background on this error at: https://sqlalche.me/e/14/e3q8)
".
[2025-03-07T09:19:43.596+0000] {logging_mixin.py:188} WARNING - Calculating Metrics:   3%|3         | 2/61 [00:00<00:03, 16.48it/s]
[2025-03-07T09:19:43.597+0000] {logging_mixin.py:188} WARNING - Calculating Metrics:   3%|3         | 2/61 [00:00<00:03, 16.48it/s]
[2025-03-07T09:19:43.601+0000] {sqlalchemy_execution_engine.py:1041} ERROR - An SQL execution Exception occurred.  OperationalError: "(psycopg2.OperationalError) connection to server at "localhost" (::1), port 5432 failed: Connection refused
	Is the server running on that host and accepting TCP/IP connections?
connection to server at "localhost" (127.0.0.1), port 5432 failed: Connection refused
	Is the server running on that host and accepting TCP/IP connections?

(Background on this error at: https://sqlalche.me/e/14/e3q8)".  Traceback: "Traceback (most recent call last):
  File "/home/***/.local/lib/python3.11/site-packages/sqlalchemy/engine/base.py", line 3371, in _wrap_pool_connect
    return fn()
           ^^^^
  File "/home/***/.local/lib/python3.11/site-packages/sqlalchemy/pool/base.py", line 327, in connect
    return _ConnectionFairy._checkout(self)
           ^^^^^^^^^^^^^^^^^^^^^^^^^^^^^^^^
  File "/home/***/.local/lib/python3.11/site-packages/sqlalchemy/pool/base.py", line 894, in _checkout
    fairy = _ConnectionRecord.checkout(pool)
            ^^^^^^^^^^^^^^^^^^^^^^^^^^^^^^^^
  File "/home/***/.local/lib/python3.11/site-packages/sqlalchemy/pool/base.py", line 493, in checkout
    rec = pool._do_get()
          ^^^^^^^^^^^^^^
  File "/home/***/.local/lib/python3.11/site-packages/sqlalchemy/pool/impl.py", line 145, in _do_get
    with util.safe_reraise():
  File "/home/***/.local/lib/python3.11/site-packages/sqlalchemy/util/langhelpers.py", line 70, in __exit__
    compat.raise_(
  File "/home/***/.local/lib/python3.11/site-packages/sqlalchemy/util/compat.py", line 211, in raise_
    raise exception
  File "/home/***/.local/lib/python3.11/site-packages/sqlalchemy/pool/impl.py", line 143, in _do_get
    return self._create_connection()
           ^^^^^^^^^^^^^^^^^^^^^^^^^
  File "/home/***/.local/lib/python3.11/site-packages/sqlalchemy/pool/base.py", line 273, in _create_connection
    return _ConnectionRecord(self)
           ^^^^^^^^^^^^^^^^^^^^^^^
  File "/home/***/.local/lib/python3.11/site-packages/sqlalchemy/pool/base.py", line 388, in __init__
    self.__connect()
  File "/home/***/.local/lib/python3.11/site-packages/sqlalchemy/pool/base.py", line 690, in __connect
    with util.safe_reraise():
  File "/home/***/.local/lib/python3.11/site-packages/sqlalchemy/util/langhelpers.py", line 70, in __exit__
    compat.raise_(
  File "/home/***/.local/lib/python3.11/site-packages/sqlalchemy/util/compat.py", line 211, in raise_
    raise exception
  File "/home/***/.local/lib/python3.11/site-packages/sqlalchemy/pool/base.py", line 686, in __connect
    self.dbapi_connection = connection = pool._invoke_creator(self)
                                         ^^^^^^^^^^^^^^^^^^^^^^^^^^
  File "/home/***/.local/lib/python3.11/site-packages/sqlalchemy/engine/create.py", line 574, in connect
    return dialect.connect(*cargs, **cparams)
           ^^^^^^^^^^^^^^^^^^^^^^^^^^^^^^^^^^
  File "/home/***/.local/lib/python3.11/site-packages/sqlalchemy/engine/default.py", line 598, in connect
    return self.dbapi.connect(*cargs, **cparams)
           ^^^^^^^^^^^^^^^^^^^^^^^^^^^^^^^^^^^^^
  File "/home/***/.local/lib/python3.11/site-packages/psycopg2/__init__.py", line 122, in connect
    conn = _connect(dsn, connection_factory=connection_factory, **kwasync)
           ^^^^^^^^^^^^^^^^^^^^^^^^^^^^^^^^^^^^^^^^^^^^^^^^^^^^^^^^^^^^^^^
psycopg2.OperationalError: connection to server at "localhost" (::1), port 5432 failed: Connection refused
	Is the server running on that host and accepting TCP/IP connections?
connection to server at "localhost" (127.0.0.1), port 5432 failed: Connection refused
	Is the server running on that host and accepting TCP/IP connections?


The above exception was the direct cause of the following exception:

Traceback (most recent call last):
  File "/home/***/.local/lib/python3.11/site-packages/great_expectations/execution_engine/sqlalchemy_execution_engine.py", line 1029, in resolve_metric_bundle
    res = self.execute_query(sa_query_object).fetchall()
          ^^^^^^^^^^^^^^^^^^^^^^^^^^^^^^^^^^^
  File "/home/***/.local/lib/python3.11/site-packages/great_expectations/execution_engine/sqlalchemy_execution_engine.py", line 1319, in execute_query
    with self.get_connection() as connection:
  File "/usr/local/lib/python3.11/contextlib.py", line 137, in __enter__
    return next(self.gen)
           ^^^^^^^^^^^^^^
  File "/home/***/.local/lib/python3.11/site-packages/great_expectations/execution_engine/sqlalchemy_execution_engine.py", line 1304, in get_connection
    with self.engine.connect() as connection:
         ^^^^^^^^^^^^^^^^^^^^^
  File "/home/***/.local/lib/python3.11/site-packages/sqlalchemy/engine/base.py", line 3325, in connect
    return self._connection_cls(self, close_with_result=close_with_result)
           ^^^^^^^^^^^^^^^^^^^^^^^^^^^^^^^^^^^^^^^^^^^^^^^^^^^^^^^^^^^^^^^
  File "/home/***/.local/lib/python3.11/site-packages/sqlalchemy/engine/base.py", line 96, in __init__
    else engine.raw_connection()
         ^^^^^^^^^^^^^^^^^^^^^^^
  File "/home/***/.local/lib/python3.11/site-packages/sqlalchemy/engine/base.py", line 3404, in raw_connection
    return self._wrap_pool_connect(self.pool.connect, _connection)
           ^^^^^^^^^^^^^^^^^^^^^^^^^^^^^^^^^^^^^^^^^^^^^^^^^^^^^^^
  File "/home/***/.local/lib/python3.11/site-packages/sqlalchemy/engine/base.py", line 3374, in _wrap_pool_connect
    Connection._handle_dbapi_exception_noconnection(
  File "/home/***/.local/lib/python3.11/site-packages/sqlalchemy/engine/base.py", line 2208, in _handle_dbapi_exception_noconnection
    util.raise_(
  File "/home/***/.local/lib/python3.11/site-packages/sqlalchemy/util/compat.py", line 211, in raise_
    raise exception
  File "/home/***/.local/lib/python3.11/site-packages/sqlalchemy/engine/base.py", line 3371, in _wrap_pool_connect
    return fn()
           ^^^^
  File "/home/***/.local/lib/python3.11/site-packages/sqlalchemy/pool/base.py", line 327, in connect
    return _ConnectionFairy._checkout(self)
           ^^^^^^^^^^^^^^^^^^^^^^^^^^^^^^^^
  File "/home/***/.local/lib/python3.11/site-packages/sqlalchemy/pool/base.py", line 894, in _checkout
    fairy = _ConnectionRecord.checkout(pool)
            ^^^^^^^^^^^^^^^^^^^^^^^^^^^^^^^^
  File "/home/***/.local/lib/python3.11/site-packages/sqlalchemy/pool/base.py", line 493, in checkout
    rec = pool._do_get()
          ^^^^^^^^^^^^^^
  File "/home/***/.local/lib/python3.11/site-packages/sqlalchemy/pool/impl.py", line 145, in _do_get
    with util.safe_reraise():
  File "/home/***/.local/lib/python3.11/site-packages/sqlalchemy/util/langhelpers.py", line 70, in __exit__
    compat.raise_(
  File "/home/***/.local/lib/python3.11/site-packages/sqlalchemy/util/compat.py", line 211, in raise_
    raise exception
  File "/home/***/.local/lib/python3.11/site-packages/sqlalchemy/pool/impl.py", line 143, in _do_get
    return self._create_connection()
           ^^^^^^^^^^^^^^^^^^^^^^^^^
  File "/home/***/.local/lib/python3.11/site-packages/sqlalchemy/pool/base.py", line 273, in _create_connection
    return _ConnectionRecord(self)
           ^^^^^^^^^^^^^^^^^^^^^^^
  File "/home/***/.local/lib/python3.11/site-packages/sqlalchemy/pool/base.py", line 388, in __init__
    self.__connect()
  File "/home/***/.local/lib/python3.11/site-packages/sqlalchemy/pool/base.py", line 690, in __connect
    with util.safe_reraise():
  File "/home/***/.local/lib/python3.11/site-packages/sqlalchemy/util/langhelpers.py", line 70, in __exit__
    compat.raise_(
  File "/home/***/.local/lib/python3.11/site-packages/sqlalchemy/util/compat.py", line 211, in raise_
    raise exception
  File "/home/***/.local/lib/python3.11/site-packages/sqlalchemy/pool/base.py", line 686, in __connect
    self.dbapi_connection = connection = pool._invoke_creator(self)
                                         ^^^^^^^^^^^^^^^^^^^^^^^^^^
  File "/home/***/.local/lib/python3.11/site-packages/sqlalchemy/engine/create.py", line 574, in connect
    return dialect.connect(*cargs, **cparams)
           ^^^^^^^^^^^^^^^^^^^^^^^^^^^^^^^^^^
  File "/home/***/.local/lib/python3.11/site-packages/sqlalchemy/engine/default.py", line 598, in connect
    return self.dbapi.connect(*cargs, **cparams)
           ^^^^^^^^^^^^^^^^^^^^^^^^^^^^^^^^^^^^^
  File "/home/***/.local/lib/python3.11/site-packages/psycopg2/__init__.py", line 122, in connect
    conn = _connect(dsn, connection_factory=connection_factory, **kwasync)
           ^^^^^^^^^^^^^^^^^^^^^^^^^^^^^^^^^^^^^^^^^^^^^^^^^^^^^^^^^^^^^^^
sqlalchemy.exc.OperationalError: (psycopg2.OperationalError) connection to server at "localhost" (::1), port 5432 failed: Connection refused
	Is the server running on that host and accepting TCP/IP connections?
connection to server at "localhost" (127.0.0.1), port 5432 failed: Connection refused
	Is the server running on that host and accepting TCP/IP connections?

(Background on this error at: https://sqlalche.me/e/14/e3q8)
".
[2025-03-07T09:19:43.631+0000] {logging_mixin.py:188} WARNING - Calculating Metrics:   3%|3         | 2/61 [00:00<00:03, 16.48it/s]
[2025-03-07T09:19:43.635+0000] {sqlalchemy_execution_engine.py:1041} ERROR - An SQL execution Exception occurred.  OperationalError: "(psycopg2.OperationalError) connection to server at "localhost" (::1), port 5432 failed: Connection refused
	Is the server running on that host and accepting TCP/IP connections?
connection to server at "localhost" (127.0.0.1), port 5432 failed: Connection refused
	Is the server running on that host and accepting TCP/IP connections?

(Background on this error at: https://sqlalche.me/e/14/e3q8)".  Traceback: "Traceback (most recent call last):
  File "/home/***/.local/lib/python3.11/site-packages/sqlalchemy/engine/base.py", line 3371, in _wrap_pool_connect
    return fn()
           ^^^^
  File "/home/***/.local/lib/python3.11/site-packages/sqlalchemy/pool/base.py", line 327, in connect
    return _ConnectionFairy._checkout(self)
           ^^^^^^^^^^^^^^^^^^^^^^^^^^^^^^^^
  File "/home/***/.local/lib/python3.11/site-packages/sqlalchemy/pool/base.py", line 894, in _checkout
    fairy = _ConnectionRecord.checkout(pool)
            ^^^^^^^^^^^^^^^^^^^^^^^^^^^^^^^^
  File "/home/***/.local/lib/python3.11/site-packages/sqlalchemy/pool/base.py", line 493, in checkout
    rec = pool._do_get()
          ^^^^^^^^^^^^^^
  File "/home/***/.local/lib/python3.11/site-packages/sqlalchemy/pool/impl.py", line 145, in _do_get
    with util.safe_reraise():
  File "/home/***/.local/lib/python3.11/site-packages/sqlalchemy/util/langhelpers.py", line 70, in __exit__
    compat.raise_(
  File "/home/***/.local/lib/python3.11/site-packages/sqlalchemy/util/compat.py", line 211, in raise_
    raise exception
  File "/home/***/.local/lib/python3.11/site-packages/sqlalchemy/pool/impl.py", line 143, in _do_get
    return self._create_connection()
           ^^^^^^^^^^^^^^^^^^^^^^^^^
  File "/home/***/.local/lib/python3.11/site-packages/sqlalchemy/pool/base.py", line 273, in _create_connection
    return _ConnectionRecord(self)
           ^^^^^^^^^^^^^^^^^^^^^^^
  File "/home/***/.local/lib/python3.11/site-packages/sqlalchemy/pool/base.py", line 388, in __init__
    self.__connect()
  File "/home/***/.local/lib/python3.11/site-packages/sqlalchemy/pool/base.py", line 690, in __connect
    with util.safe_reraise():
  File "/home/***/.local/lib/python3.11/site-packages/sqlalchemy/util/langhelpers.py", line 70, in __exit__
    compat.raise_(
  File "/home/***/.local/lib/python3.11/site-packages/sqlalchemy/util/compat.py", line 211, in raise_
    raise exception
  File "/home/***/.local/lib/python3.11/site-packages/sqlalchemy/pool/base.py", line 686, in __connect
    self.dbapi_connection = connection = pool._invoke_creator(self)
                                         ^^^^^^^^^^^^^^^^^^^^^^^^^^
  File "/home/***/.local/lib/python3.11/site-packages/sqlalchemy/engine/create.py", line 574, in connect
    return dialect.connect(*cargs, **cparams)
           ^^^^^^^^^^^^^^^^^^^^^^^^^^^^^^^^^^
  File "/home/***/.local/lib/python3.11/site-packages/sqlalchemy/engine/default.py", line 598, in connect
    return self.dbapi.connect(*cargs, **cparams)
           ^^^^^^^^^^^^^^^^^^^^^^^^^^^^^^^^^^^^^
  File "/home/***/.local/lib/python3.11/site-packages/psycopg2/__init__.py", line 122, in connect
    conn = _connect(dsn, connection_factory=connection_factory, **kwasync)
           ^^^^^^^^^^^^^^^^^^^^^^^^^^^^^^^^^^^^^^^^^^^^^^^^^^^^^^^^^^^^^^^
psycopg2.OperationalError: connection to server at "localhost" (::1), port 5432 failed: Connection refused
	Is the server running on that host and accepting TCP/IP connections?
connection to server at "localhost" (127.0.0.1), port 5432 failed: Connection refused
	Is the server running on that host and accepting TCP/IP connections?


The above exception was the direct cause of the following exception:

Traceback (most recent call last):
  File "/home/***/.local/lib/python3.11/site-packages/great_expectations/execution_engine/sqlalchemy_execution_engine.py", line 1029, in resolve_metric_bundle
    res = self.execute_query(sa_query_object).fetchall()
          ^^^^^^^^^^^^^^^^^^^^^^^^^^^^^^^^^^^
  File "/home/***/.local/lib/python3.11/site-packages/great_expectations/execution_engine/sqlalchemy_execution_engine.py", line 1319, in execute_query
    with self.get_connection() as connection:
  File "/usr/local/lib/python3.11/contextlib.py", line 137, in __enter__
    return next(self.gen)
           ^^^^^^^^^^^^^^
  File "/home/***/.local/lib/python3.11/site-packages/great_expectations/execution_engine/sqlalchemy_execution_engine.py", line 1304, in get_connection
    with self.engine.connect() as connection:
         ^^^^^^^^^^^^^^^^^^^^^
  File "/home/***/.local/lib/python3.11/site-packages/sqlalchemy/engine/base.py", line 3325, in connect
    return self._connection_cls(self, close_with_result=close_with_result)
           ^^^^^^^^^^^^^^^^^^^^^^^^^^^^^^^^^^^^^^^^^^^^^^^^^^^^^^^^^^^^^^^
  File "/home/***/.local/lib/python3.11/site-packages/sqlalchemy/engine/base.py", line 96, in __init__
    else engine.raw_connection()
         ^^^^^^^^^^^^^^^^^^^^^^^
  File "/home/***/.local/lib/python3.11/site-packages/sqlalchemy/engine/base.py", line 3404, in raw_connection
    return self._wrap_pool_connect(self.pool.connect, _connection)
           ^^^^^^^^^^^^^^^^^^^^^^^^^^^^^^^^^^^^^^^^^^^^^^^^^^^^^^^
  File "/home/***/.local/lib/python3.11/site-packages/sqlalchemy/engine/base.py", line 3374, in _wrap_pool_connect
    Connection._handle_dbapi_exception_noconnection(
  File "/home/***/.local/lib/python3.11/site-packages/sqlalchemy/engine/base.py", line 2208, in _handle_dbapi_exception_noconnection
    util.raise_(
  File "/home/***/.local/lib/python3.11/site-packages/sqlalchemy/util/compat.py", line 211, in raise_
    raise exception
  File "/home/***/.local/lib/python3.11/site-packages/sqlalchemy/engine/base.py", line 3371, in _wrap_pool_connect
    return fn()
           ^^^^
  File "/home/***/.local/lib/python3.11/site-packages/sqlalchemy/pool/base.py", line 327, in connect
    return _ConnectionFairy._checkout(self)
           ^^^^^^^^^^^^^^^^^^^^^^^^^^^^^^^^
  File "/home/***/.local/lib/python3.11/site-packages/sqlalchemy/pool/base.py", line 894, in _checkout
    fairy = _ConnectionRecord.checkout(pool)
            ^^^^^^^^^^^^^^^^^^^^^^^^^^^^^^^^
  File "/home/***/.local/lib/python3.11/site-packages/sqlalchemy/pool/base.py", line 493, in checkout
    rec = pool._do_get()
          ^^^^^^^^^^^^^^
  File "/home/***/.local/lib/python3.11/site-packages/sqlalchemy/pool/impl.py", line 145, in _do_get
    with util.safe_reraise():
  File "/home/***/.local/lib/python3.11/site-packages/sqlalchemy/util/langhelpers.py", line 70, in __exit__
    compat.raise_(
  File "/home/***/.local/lib/python3.11/site-packages/sqlalchemy/util/compat.py", line 211, in raise_
    raise exception
  File "/home/***/.local/lib/python3.11/site-packages/sqlalchemy/pool/impl.py", line 143, in _do_get
    return self._create_connection()
           ^^^^^^^^^^^^^^^^^^^^^^^^^
  File "/home/***/.local/lib/python3.11/site-packages/sqlalchemy/pool/base.py", line 273, in _create_connection
    return _ConnectionRecord(self)
           ^^^^^^^^^^^^^^^^^^^^^^^
  File "/home/***/.local/lib/python3.11/site-packages/sqlalchemy/pool/base.py", line 388, in __init__
    self.__connect()
  File "/home/***/.local/lib/python3.11/site-packages/sqlalchemy/pool/base.py", line 690, in __connect
    with util.safe_reraise():
  File "/home/***/.local/lib/python3.11/site-packages/sqlalchemy/util/langhelpers.py", line 70, in __exit__
    compat.raise_(
  File "/home/***/.local/lib/python3.11/site-packages/sqlalchemy/util/compat.py", line 211, in raise_
    raise exception
  File "/home/***/.local/lib/python3.11/site-packages/sqlalchemy/pool/base.py", line 686, in __connect
    self.dbapi_connection = connection = pool._invoke_creator(self)
                                         ^^^^^^^^^^^^^^^^^^^^^^^^^^
  File "/home/***/.local/lib/python3.11/site-packages/sqlalchemy/engine/create.py", line 574, in connect
    return dialect.connect(*cargs, **cparams)
           ^^^^^^^^^^^^^^^^^^^^^^^^^^^^^^^^^^
  File "/home/***/.local/lib/python3.11/site-packages/sqlalchemy/engine/default.py", line 598, in connect
    return self.dbapi.connect(*cargs, **cparams)
           ^^^^^^^^^^^^^^^^^^^^^^^^^^^^^^^^^^^^^
  File "/home/***/.local/lib/python3.11/site-packages/psycopg2/__init__.py", line 122, in connect
    conn = _connect(dsn, connection_factory=connection_factory, **kwasync)
           ^^^^^^^^^^^^^^^^^^^^^^^^^^^^^^^^^^^^^^^^^^^^^^^^^^^^^^^^^^^^^^^
sqlalchemy.exc.OperationalError: (psycopg2.OperationalError) connection to server at "localhost" (::1), port 5432 failed: Connection refused
	Is the server running on that host and accepting TCP/IP connections?
connection to server at "localhost" (127.0.0.1), port 5432 failed: Connection refused
	Is the server running on that host and accepting TCP/IP connections?

(Background on this error at: https://sqlalche.me/e/14/e3q8)
".
[2025-03-07T09:19:43.662+0000] {logging_mixin.py:188} WARNING - Calculating Metrics:   3%|3         | 2/61 [00:00<00:03, 16.48it/s]
[2025-03-07T09:19:43.663+0000] {logging_mixin.py:188} WARNING - Calculating Metrics:   3%|3         | 2/61 [00:00<00:03, 16.48it/s]
[2025-03-07T09:19:43.663+0000] {logging_mixin.py:188} WARNING - Calculating Metrics:   3%|3         | 2/61 [00:00<00:08,  6.60it/s]
[2025-03-07T09:19:44.127+0000] {python.py:237} INFO - Done. Returned value was: None
[2025-03-07T09:19:44.127+0000] {taskinstance.py:441} INFO - ::group::Post task execution logs
[2025-03-07T09:19:44.138+0000] {taskinstance.py:1205} INFO - Marking task as SUCCESS. dag_id=clientes_dag, task_id=gx_run_audit, execution_date=20250307T091939, start_date=20250307T091942, end_date=20250307T091944
[2025-03-07T09:19:44.166+0000] {local_task_job_runner.py:240} INFO - Task exited with return code 0
[2025-03-07T09:19:44.182+0000] {taskinstance.py:3482} INFO - 0 downstream tasks scheduled from follow-on schedule check
[2025-03-07T09:19:44.184+0000] {local_task_job_runner.py:222} INFO - ::endgroup::
