[2025-03-06T15:32:12.402+0000] {local_task_job_runner.py:120} INFO - ::group::Pre task execution logs
[2025-03-06T15:32:12.453+0000] {taskinstance.py:2073} INFO - Dependencies all met for dep_context=non-requeueable deps ti=<TaskInstance: clientes_dag.gx_run_audit manual__2025-03-06T15:32:08.651571+00:00 [queued]>
[2025-03-06T15:32:12.465+0000] {taskinstance.py:2073} INFO - Dependencies all met for dep_context=requeueable deps ti=<TaskInstance: clientes_dag.gx_run_audit manual__2025-03-06T15:32:08.651571+00:00 [queued]>
[2025-03-06T15:32:12.465+0000] {taskinstance.py:2303} INFO - Starting attempt 1 of 1
[2025-03-06T15:32:12.486+0000] {taskinstance.py:2327} INFO - Executing <Task(PythonOperator): gx_run_audit> on 2025-03-06 15:32:08.651571+00:00
[2025-03-06T15:32:12.496+0000] {standard_task_runner.py:63} INFO - Started process 6310 to run task
[2025-03-06T15:32:12.502+0000] {standard_task_runner.py:90} INFO - Running: ['***', 'tasks', 'run', 'clientes_dag', 'gx_run_audit', 'manual__2025-03-06T15:32:08.651571+00:00', '--job-id', '10', '--raw', '--subdir', 'DAGS_FOLDER/clientes_dag.py', '--cfg-path', '/tmp/tmp_812ferk']
[2025-03-06T15:32:12.507+0000] {standard_task_runner.py:91} INFO - Job 10: Subtask gx_run_audit
[2025-03-06T15:32:12.577+0000] {task_command.py:426} INFO - Running <TaskInstance: clientes_dag.gx_run_audit manual__2025-03-06T15:32:08.651571+00:00 [running]> on host a3d267d0ec58
[2025-03-06T15:32:12.936+0000] {taskinstance.py:2644} INFO - Exporting env vars: AIRFLOW_CTX_DAG_OWNER='***' AIRFLOW_CTX_DAG_ID='clientes_dag' AIRFLOW_CTX_TASK_ID='gx_run_audit' AIRFLOW_CTX_EXECUTION_DATE='2025-03-06T15:32:08.651571+00:00' AIRFLOW_CTX_TRY_NUMBER='1' AIRFLOW_CTX_DAG_RUN_ID='manual__2025-03-06T15:32:08.651571+00:00'
[2025-03-06T15:32:12.938+0000] {taskinstance.py:430} INFO - ::endgroup::
[2025-03-06T15:32:12.995+0000] {file_data_context.py:209} INFO - FileDataContext loading fluent config
[2025-03-06T15:32:12.998+0000] {config.py:191} INFO - Loading 'datasources' ->
[{'assets': [...],
  'connection_string': 'postgresql+psycopg2://postgres:postgres@127.0.0.1/postgres',
  'id': '90eb4e6e-b86f-454c-b3ed-67111cd6ec30',
  'name': 'pg_datasource',
  'type': 'postgres'}]
[2025-03-06T15:32:13.026+0000] {abstract_data_context.py:2416} INFO - Loaded 'pg_datasource' from fluent config
[2025-03-06T15:32:13.028+0000] {taskinstance.py:441} INFO - ::group::Post task execution logs
[2025-03-06T15:32:13.028+0000] {taskinstance.py:2890} ERROR - Task failed with exception
Traceback (most recent call last):
  File "/home/airflow/.local/lib/python3.11/site-packages/airflow/models/taskinstance.py", line 465, in _execute_task
    result = _execute_callable(context=context, **execute_callable_kwargs)
             ^^^^^^^^^^^^^^^^^^^^^^^^^^^^^^^^^^^^^^^^^^^^^^^^^^^^^^^^^^^^^
  File "/home/airflow/.local/lib/python3.11/site-packages/airflow/models/taskinstance.py", line 432, in _execute_callable
    return execute_callable(context=context, **execute_callable_kwargs)
           ^^^^^^^^^^^^^^^^^^^^^^^^^^^^^^^^^^^^^^^^^^^^^^^^^^^^^^^^^^^^
  File "/home/airflow/.local/lib/python3.11/site-packages/airflow/models/baseoperator.py", line 400, in wrapper
    return func(self, *args, **kwargs)
           ^^^^^^^^^^^^^^^^^^^^^^^^^^^
  File "/home/airflow/.local/lib/python3.11/site-packages/airflow/operators/python.py", line 235, in execute
    return_value = self.execute_callable()
                   ^^^^^^^^^^^^^^^^^^^^^^^
  File "/home/airflow/.local/lib/python3.11/site-packages/airflow/operators/python.py", line 252, in execute_callable
    return self.python_callable(*self.op_args, **self.op_kwargs)
           ^^^^^^^^^^^^^^^^^^^^^^^^^^^^^^^^^^^^^^^^^^^^^^^^^^^^^
  File "/opt/airflow/dags/clientes_dag.py", line 8, in run_gx_checkpoint
    context.checkpoints.get("Checkpoint").run()
    ^^^^^^^^^^^^^^^^^^^^^^^^^^^^^^^^^^^^^
  File "/home/airflow/.local/lib/python3.11/site-packages/great_expectations/core/factory/checkpoint_factory.py", line 101, in get
    raise DataContextError(f"Checkpoint with name {name} was not found.")  # noqa: TRY003
    ^^^^^^^^^^^^^^^^^^^^^^^^^^^^^^^^^^^^^^^^^^^^^^^^^^^^^^^^^^^^^^^^^^^^^
great_expectations.exceptions.exceptions.DataContextError: Checkpoint with name Checkpoint was not found.
[2025-03-06T15:32:13.038+0000] {taskinstance.py:1205} INFO - Marking task as FAILED. dag_id=clientes_dag, task_id=gx_run_audit, execution_date=20250306T153208, start_date=20250306T153212, end_date=20250306T153213
[2025-03-06T15:32:13.060+0000] {standard_task_runner.py:110} ERROR - Failed to execute job 10 for task gx_run_audit (Checkpoint with name Checkpoint was not found.; 6310)
[2025-03-06T15:32:13.089+0000] {local_task_job_runner.py:240} INFO - Task exited with return code 1
[2025-03-06T15:32:13.114+0000] {taskinstance.py:3482} INFO - 0 downstream tasks scheduled from follow-on schedule check
[2025-03-06T15:32:13.118+0000] {local_task_job_runner.py:222} INFO - ::endgroup::
