[2025-03-06T15:41:18.873+0000] {local_task_job_runner.py:120} INFO - ::group::Pre task execution logs
[2025-03-06T15:41:18.899+0000] {taskinstance.py:2073} INFO - Dependencies all met for dep_context=non-requeueable deps ti=<TaskInstance: clientes_dag.gx_run_audit manual__2025-03-06T15:41:15.069840+00:00 [queued]>
[2025-03-06T15:41:18.908+0000] {taskinstance.py:2073} INFO - Dependencies all met for dep_context=requeueable deps ti=<TaskInstance: clientes_dag.gx_run_audit manual__2025-03-06T15:41:15.069840+00:00 [queued]>
[2025-03-06T15:41:18.909+0000] {taskinstance.py:2303} INFO - Starting attempt 1 of 1
[2025-03-06T15:41:18.927+0000] {taskinstance.py:2327} INFO - Executing <Task(PythonOperator): gx_run_audit> on 2025-03-06 15:41:15.069840+00:00
[2025-03-06T15:41:18.938+0000] {standard_task_runner.py:63} INFO - Started process 6546 to run task
[2025-03-06T15:41:18.943+0000] {standard_task_runner.py:90} INFO - Running: ['***', 'tasks', 'run', 'clientes_dag', 'gx_run_audit', 'manual__2025-03-06T15:41:15.069840+00:00', '--job-id', '11', '--raw', '--subdir', 'DAGS_FOLDER/clientes_dag.py', '--cfg-path', '/tmp/tmp0yw6wg0w']
[2025-03-06T15:41:18.948+0000] {standard_task_runner.py:91} INFO - Job 11: Subtask gx_run_audit
[2025-03-06T15:41:19.022+0000] {task_command.py:426} INFO - Running <TaskInstance: clientes_dag.gx_run_audit manual__2025-03-06T15:41:15.069840+00:00 [running]> on host a3d267d0ec58
[2025-03-06T15:41:19.366+0000] {taskinstance.py:2644} INFO - Exporting env vars: AIRFLOW_CTX_DAG_OWNER='***' AIRFLOW_CTX_DAG_ID='clientes_dag' AIRFLOW_CTX_TASK_ID='gx_run_audit' AIRFLOW_CTX_EXECUTION_DATE='2025-03-06T15:41:15.069840+00:00' AIRFLOW_CTX_TRY_NUMBER='1' AIRFLOW_CTX_DAG_RUN_ID='manual__2025-03-06T15:41:15.069840+00:00'
[2025-03-06T15:41:19.369+0000] {taskinstance.py:430} INFO - ::endgroup::
[2025-03-06T15:41:19.415+0000] {file_data_context.py:209} INFO - FileDataContext loading fluent config
[2025-03-06T15:41:19.420+0000] {config.py:191} INFO - Loading 'datasources' ->
[{'assets': [...],
  'connection_string': 'postgresql+psycopg2://postgres:postgres@127.0.0.1:5432/postgres',
  'id': '22e301ff-cc54-4bc9-a651-fa16a02d19f7',
  'name': 'pg_datasource',
  'type': 'postgres'}]
[2025-03-06T15:41:19.457+0000] {abstract_data_context.py:2416} INFO - Loaded 'pg_datasource' from fluent config
[2025-03-06T15:41:19.460+0000] {taskinstance.py:441} INFO - ::group::Post task execution logs
[2025-03-06T15:41:19.460+0000] {taskinstance.py:2890} ERROR - Task failed with exception
Traceback (most recent call last):
  File "/home/airflow/.local/lib/python3.11/site-packages/airflow/models/taskinstance.py", line 465, in _execute_task
    result = _execute_callable(context=context, **execute_callable_kwargs)
             ^^^^^^^^^^^^^^^^^^^^^^^^^^^^^^^^^^^^^^^^^^^^^^^^^^^^^^^^^^^^^
  File "/home/airflow/.local/lib/python3.11/site-packages/airflow/models/taskinstance.py", line 432, in _execute_callable
    return execute_callable(context=context, **execute_callable_kwargs)
           ^^^^^^^^^^^^^^^^^^^^^^^^^^^^^^^^^^^^^^^^^^^^^^^^^^^^^^^^^^^^
  File "/home/airflow/.local/lib/python3.11/site-packages/airflow/models/baseoperator.py", line 400, in wrapper
    return func(self, *args, **kwargs)
           ^^^^^^^^^^^^^^^^^^^^^^^^^^^
  File "/home/airflow/.local/lib/python3.11/site-packages/airflow/operators/python.py", line 235, in execute
    return_value = self.execute_callable()
                   ^^^^^^^^^^^^^^^^^^^^^^^
  File "/home/airflow/.local/lib/python3.11/site-packages/airflow/operators/python.py", line 252, in execute_callable
    return self.python_callable(*self.op_args, **self.op_kwargs)
           ^^^^^^^^^^^^^^^^^^^^^^^^^^^^^^^^^^^^^^^^^^^^^^^^^^^^^
  File "/opt/airflow/dags/clientes_dag.py", line 8, in run_gx_checkpoint
    context.checkpoints.get("Checkpoint").run()
    ^^^^^^^^^^^^^^^^^^^^^^^^^^^^^^^^^^^^^
  File "/home/airflow/.local/lib/python3.11/site-packages/great_expectations/core/factory/checkpoint_factory.py", line 101, in get
    raise DataContextError(f"Checkpoint with name {name} was not found.")  # noqa: TRY003
    ^^^^^^^^^^^^^^^^^^^^^^^^^^^^^^^^^^^^^^^^^^^^^^^^^^^^^^^^^^^^^^^^^^^^^
great_expectations.exceptions.exceptions.DataContextError: Checkpoint with name Checkpoint was not found.
[2025-03-06T15:41:19.471+0000] {taskinstance.py:1205} INFO - Marking task as FAILED. dag_id=clientes_dag, task_id=gx_run_audit, execution_date=20250306T154115, start_date=20250306T154118, end_date=20250306T154119
[2025-03-06T15:41:19.485+0000] {standard_task_runner.py:110} ERROR - Failed to execute job 11 for task gx_run_audit (Checkpoint with name Checkpoint was not found.; 6546)
[2025-03-06T15:41:19.532+0000] {local_task_job_runner.py:240} INFO - Task exited with return code 1
[2025-03-06T15:41:19.552+0000] {taskinstance.py:3482} INFO - 0 downstream tasks scheduled from follow-on schedule check
[2025-03-06T15:41:19.555+0000] {local_task_job_runner.py:222} INFO - ::endgroup::
