[2025-03-06T10:15:18.621+0000] {local_task_job_runner.py:120} INFO - ::group::Pre task execution logs
[2025-03-06T10:15:18.632+0000] {taskinstance.py:2073} INFO - Dependencies all met for dep_context=non-requeueable deps ti=<TaskInstance: clientes_dag.write_data manual__2025-03-06T10:15:15.443315+00:00 [queued]>
[2025-03-06T10:15:18.638+0000] {taskinstance.py:2073} INFO - Dependencies all met for dep_context=requeueable deps ti=<TaskInstance: clientes_dag.write_data manual__2025-03-06T10:15:15.443315+00:00 [queued]>
[2025-03-06T10:15:18.639+0000] {taskinstance.py:2303} INFO - Starting attempt 1 of 1
[2025-03-06T10:15:18.648+0000] {taskinstance.py:2327} INFO - Executing <Task(SSHOperator): write_data> on 2025-03-06 10:15:15.443315+00:00
[2025-03-06T10:15:18.654+0000] {standard_task_runner.py:63} INFO - Started process 257 to run task
[2025-03-06T10:15:18.657+0000] {standard_task_runner.py:90} INFO - Running: ['***', 'tasks', 'run', 'clientes_dag', 'write_data', 'manual__2025-03-06T10:15:15.443315+00:00', '--job-id', '2', '--raw', '--subdir', 'DAGS_FOLDER/clientes_dag.py', '--cfg-path', '/tmp/tmp108vgqin']
[2025-03-06T10:15:18.659+0000] {standard_task_runner.py:91} INFO - Job 2: Subtask write_data
[2025-03-06T10:15:18.697+0000] {task_command.py:426} INFO - Running <TaskInstance: clientes_dag.write_data manual__2025-03-06T10:15:15.443315+00:00 [running]> on host a3d267d0ec58
[2025-03-06T10:15:18.756+0000] {taskinstance.py:2644} INFO - Exporting env vars: AIRFLOW_CTX_DAG_OWNER='***' AIRFLOW_CTX_DAG_ID='clientes_dag' AIRFLOW_CTX_TASK_ID='write_data' AIRFLOW_CTX_EXECUTION_DATE='2025-03-06T10:15:15.443315+00:00' AIRFLOW_CTX_TRY_NUMBER='1' AIRFLOW_CTX_DAG_RUN_ID='manual__2025-03-06T10:15:15.443315+00:00'
[2025-03-06T10:15:18.757+0000] {taskinstance.py:430} INFO - ::endgroup::
[2025-03-06T10:15:18.790+0000] {ssh.py:151} INFO - Creating ssh_client
[2025-03-06T10:15:18.790+0000] {ssh.py:301} WARNING - No Host Key Verification. This won't protect against Man-In-The-Middle attacks
[2025-03-06T10:15:18.803+0000] {transport.py:1909} INFO - Connected (version 2.0, client OpenSSH_9.2p1)
[2025-03-06T10:15:19.118+0000] {transport.py:1909} INFO - Authentication (publickey) successful!
[2025-03-06T10:15:19.119+0000] {ssh.py:480} INFO - Running command: dbt seed
[2025-03-06T10:15:20.766+0000] {ssh.py:526} INFO - [0m10:15:20  Running with dbt=1.9.2
[2025-03-06T10:15:20.983+0000] {ssh.py:526} INFO - [0m10:15:20  Registered adapter: postgres=1.9.0
[2025-03-06T10:15:21.040+0000] {ssh.py:526} INFO - [0m10:15:21  Encountered an error:
[2025-03-06T10:15:21.041+0000] {ssh.py:526} INFO - Compilation Error
[2025-03-06T10:15:21.041+0000] {ssh.py:526} INFO -   dbt found 3 package(s) specified in packages.yml, but only 0 package(s) installed in dbt_packages. Run "dbt deps" to install package dependencies.
[2025-03-06T10:15:21.831+0000] {taskinstance.py:441} INFO - ::group::Post task execution logs
[2025-03-06T10:15:21.838+0000] {taskinstance.py:2890} ERROR - Task failed with exception
Traceback (most recent call last):
  File "/home/airflow/.local/lib/python3.11/site-packages/airflow/models/taskinstance.py", line 465, in _execute_task
    result = _execute_callable(context=context, **execute_callable_kwargs)
             ^^^^^^^^^^^^^^^^^^^^^^^^^^^^^^^^^^^^^^^^^^^^^^^^^^^^^^^^^^^^^
  File "/home/airflow/.local/lib/python3.11/site-packages/airflow/models/taskinstance.py", line 432, in _execute_callable
    return execute_callable(context=context, **execute_callable_kwargs)
           ^^^^^^^^^^^^^^^^^^^^^^^^^^^^^^^^^^^^^^^^^^^^^^^^^^^^^^^^^^^^
  File "/home/airflow/.local/lib/python3.11/site-packages/airflow/models/baseoperator.py", line 400, in wrapper
    return func(self, *args, **kwargs)
           ^^^^^^^^^^^^^^^^^^^^^^^^^^^
  File "/home/airflow/.local/lib/python3.11/site-packages/airflow/providers/ssh/operators/ssh.py", line 191, in execute
    result = self.run_ssh_client_command(ssh_client, self.command, context=context)
             ^^^^^^^^^^^^^^^^^^^^^^^^^^^^^^^^^^^^^^^^^^^^^^^^^^^^^^^^^^^^^^^^^^^^^^
  File "/home/airflow/.local/lib/python3.11/site-packages/airflow/providers/ssh/operators/ssh.py", line 179, in run_ssh_client_command
    self.raise_for_status(exit_status, agg_stderr, context=context)
  File "/home/airflow/.local/lib/python3.11/site-packages/airflow/providers/ssh/operators/ssh.py", line 173, in raise_for_status
    raise AirflowException(f"SSH operator error: exit status = {exit_status}")
airflow.exceptions.AirflowException: SSH operator error: exit status = 2
[2025-03-06T10:15:21.842+0000] {taskinstance.py:1205} INFO - Marking task as FAILED. dag_id=clientes_dag, task_id=write_data, execution_date=20250306T101515, start_date=20250306T101518, end_date=20250306T101521
[2025-03-06T10:15:21.851+0000] {standard_task_runner.py:110} ERROR - Failed to execute job 2 for task write_data (SSH operator error: exit status = 2; 257)
[2025-03-06T10:15:21.870+0000] {local_task_job_runner.py:240} INFO - Task exited with return code 1
[2025-03-06T10:15:21.886+0000] {taskinstance.py:3482} INFO - 0 downstream tasks scheduled from follow-on schedule check
[2025-03-06T10:15:21.890+0000] {local_task_job_runner.py:222} INFO - ::endgroup::
